<?xml version="1.0" encoding="UTF-8"?>
<!-- Generated by org.testng.reporters.JUnitReportReporter -->
<testsuite hostname="svenkat" name="com.testng2.ClassK" tests="3" failures="0" timestamp="16 Nov 2012 21:02:22 GMT" time="0.016" errors="2">
  <testcase name="check1" time="0.016" classname="com.testng2.ClassK"/>
  <testcase name="check1" time="0.000" classname="com.testng2.ClassK">
    <error type="junit.framework.AssertionFailedError" message="expected:&lt;3&gt; but was:&lt;4&gt;">
      <![CDATA[junit.framework.AssertionFailedError: expected:<3> but was:<4>
	at junit.framework.Assert.fail(Assert.java:47)
	at junit.framework.Assert.failNotEquals(Assert.java:283)
	at junit.framework.Assert.assertEquals(Assert.java:64)
	at junit.framework.Assert.assertEquals(Assert.java:195)
	at junit.framework.Assert.assertEquals(Assert.java:201)
	at com.testng2.ClassK.check1(ClassK.java:50)
	at sun.reflect.NativeMethodAccessorImpl.invoke0(Native Method)
	at sun.reflect.NativeMethodAccessorImpl.invoke(Unknown Source)
	at sun.reflect.DelegatingMethodAccessorImpl.invoke(Unknown Source)
	at java.lang.reflect.Method.invoke(Unknown Source)
	at org.testng.internal.MethodInvocationHelper.invokeMethod(MethodInvocationHelper.java:80)
	at org.testng.internal.Invoker.invokeMethod(Invoker.java:714)
	at org.testng.internal.Invoker.invokeTestMethod(Invoker.java:901)
	at org.testng.internal.Invoker.invokeTestMethods(Invoker.java:1231)
	at org.testng.internal.TestMethodWorker.invokeTestMethods(TestMethodWorker.java:127)
	at org.testng.internal.TestMethodWorker.run(TestMethodWorker.java:111)
	at org.testng.TestRunner.privateRun(TestRunner.java:767)
	at org.testng.TestRunner.run(TestRunner.java:617)
	at org.testng.SuiteRunner.runTest(SuiteRunner.java:334)
	at org.testng.SuiteRunner.runSequentially(SuiteRunner.java:329)
	at org.testng.SuiteRunner.privateRun(SuiteRunner.java:291)
	at org.testng.SuiteRunner.run(SuiteRunner.java:240)
	at org.testng.SuiteRunnerWorker.runSuite(SuiteRunnerWorker.java:52)
	at org.testng.SuiteRunnerWorker.run(SuiteRunnerWorker.java:86)
	at org.testng.TestNG.runSuitesSequentially(TestNG.java:1197)
	at org.testng.TestNG.runSuitesLocally(TestNG.java:1122)
	at org.testng.TestNG.run(TestNG.java:1030)
	at org.testng.remote.RemoteTestNG.run(RemoteTestNG.java:111)
	at org.testng.remote.RemoteTestNG.initAndRun(RemoteTestNG.java:204)
	at org.testng.remote.RemoteTestNG.main(RemoteTestNG.java:175)
]]>
    </error>
  </testcase> <!-- check1 -->
  <testcase name="check1" time="0.000" classname="com.testng2.ClassK">
    <error type="junit.framework.AssertionFailedError" message="expected:&lt;3&gt; but was:&lt;2&gt;">
      <![CDATA[junit.framework.AssertionFailedError: expected:<3> but was:<2>
	at junit.framework.Assert.fail(Assert.java:47)
	at junit.framework.Assert.failNotEquals(Assert.java:283)
	at junit.framework.Assert.assertEquals(Assert.java:64)
	at junit.framework.Assert.assertEquals(Assert.java:195)
	at junit.framework.Assert.assertEquals(Assert.java:201)
	at com.testng2.ClassK.check1(ClassK.java:50)
	at sun.reflect.NativeMethodAccessorImpl.invoke0(Native Method)
	at sun.reflect.NativeMethodAccessorImpl.invoke(Unknown Source)
	at sun.reflect.DelegatingMethodAccessorImpl.invoke(Unknown Source)
	at java.lang.reflect.Method.invoke(Unknown Source)
	at org.testng.internal.MethodInvocationHelper.invokeMethod(MethodInvocationHelper.java:80)
	at org.testng.internal.Invoker.invokeMethod(Invoker.java:714)
	at org.testng.internal.Invoker.invokeTestMethod(Invoker.java:901)
	at org.testng.internal.Invoker.invokeTestMethods(Invoker.java:1231)
	at org.testng.internal.TestMethodWorker.invokeTestMethods(TestMethodWorker.java:127)
	at org.testng.internal.TestMethodWorker.run(TestMethodWorker.java:111)
	at org.testng.TestRunner.privateRun(TestRunner.java:767)
	at org.testng.TestRunner.run(TestRunner.java:617)
	at org.testng.SuiteRunner.runTest(SuiteRunner.java:334)
	at org.testng.SuiteRunner.runSequentially(SuiteRunner.java:329)
	at org.testng.SuiteRunner.privateRun(SuiteRunner.java:291)
	at org.testng.SuiteRunner.run(SuiteRunner.java:240)
	at org.testng.SuiteRunnerWorker.runSuite(SuiteRunnerWorker.java:52)
	at org.testng.SuiteRunnerWorker.run(SuiteRunnerWorker.java:86)
	at org.testng.TestNG.runSuitesSequentially(TestNG.java:1197)
	at org.testng.TestNG.runSuitesLocally(TestNG.java:1122)
	at org.testng.TestNG.run(TestNG.java:1030)
	at org.testng.remote.RemoteTestNG.run(RemoteTestNG.java:111)
	at org.testng.remote.RemoteTestNG.initAndRun(RemoteTestNG.java:204)
	at org.testng.remote.RemoteTestNG.main(RemoteTestNG.java:175)
]]>
    </error>
  </testcase> <!-- check1 -->
</testsuite> <!-- com.testng2.ClassK -->
